
Using cuda device
TypeError: only size-1 arrays can be converted to Python scalars
The above exception was the direct cause of the following exception:
Traceback (most recent call last):
  File "/home/dang/.local/lib/python3.7/site-packages/IPython/core/interactiveshell.py", line 3296, in run_code
    exec(code_obj, self.user_global_ns, self.user_ns)
  File "<ipython-input-4-90d31a9f01e3>", line 8, in <module>
    model.learn(total_timesteps=2000000)  # 2m steps is about 8h at 70 FPS
  File "/home/dang/anaconda3/envs/mine/lib/python3.7/site-packages/stable_baselines3/ppo/ppo.py", line 308, in learn
    reset_num_timesteps=reset_num_timesteps,
  File "/home/dang/anaconda3/envs/mine/lib/python3.7/site-packages/stable_baselines3/common/on_policy_algorithm.py", line 227, in learn
    total_timesteps, eval_env, callback, eval_freq, n_eval_episodes, eval_log_path, reset_num_timesteps, tb_log_name
  File "/home/dang/anaconda3/envs/mine/lib/python3.7/site-packages/stable_baselines3/common/base_class.py", line 420, in _setup_learn
    self._last_obs = self.env.reset()  # pytype: disable=annotation-type-mismatch
  File "/home/dang/anaconda3/envs/mine/lib/python3.7/site-packages/stable_baselines3/common/vec_env/dummy_vec_env.py", line 62, in reset
    self._save_obs(env_idx, obs)
  File "/home/dang/anaconda3/envs/mine/lib/python3.7/site-packages/stable_baselines3/common/vec_env/dummy_vec_env.py", line 92, in _save_obs
    self.buf_obs[key][env_idx] = obs
