Using cuda device
Wrapping the env in a VecTransposeImage.
Traceback (most recent call last):
  File "/home/dang/.local/lib/python3.7/site-packages/IPython/core/interactiveshell.py", line 3296, in run_code
    exec(code_obj, self.user_global_ns, self.user_ns)
  File "<ipython-input-2-743558a4a9c0>", line 179, in <module>
    model.learn(total_timesteps=2000000)  # 2m steps is about 8h at 70 FPS
  File "/home/dang/anaconda3/envs/mine/lib/python3.7/site-packages/stable_baselines3/ppo/ppo.py", line 308, in learn
    reset_num_timesteps=reset_num_timesteps,
  File "/home/dang/anaconda3/envs/mine/lib/python3.7/site-packages/stable_baselines3/common/on_policy_algorithm.py", line 227, in learn
    total_timesteps, eval_env, callback, eval_freq, n_eval_episodes, eval_log_path, reset_num_timesteps, tb_log_name
  File "/home/dang/anaconda3/envs/mine/lib/python3.7/site-packages/stable_baselines3/common/base_class.py", line 420, in _setup_learn
    self._last_obs = self.env.reset()  # pytype: disable=annotation-type-mismatch
  File "/home/dang/anaconda3/envs/mine/lib/python3.7/site-packages/stable_baselines3/common/vec_env/vec_transpose.py", line 98, in reset
    return self.transpose_observations(self.venv.reset())
  File "/home/dang/anaconda3/envs/mine/lib/python3.7/site-packages/stable_baselines3/common/vec_env/dummy_vec_env.py", line 61, in reset
    obs = self.envs[env_idx].reset()
  File "/home/dang/anaconda3/envs/mine/lib/python3.7/site-packages/gym/wrappers/record_episode_statistics.py", line 17, in reset
    observation = super(RecordEpisodeStatistics, self).reset(**kwargs)
  File "/home/dang/anaconda3/envs/mine/lib/python3.7/site-packages/gym/core.py", line 237, in reset
    return self.env.reset(**kwargs)
  File "/home/dang/anaconda3/envs/mine/lib/python3.7/site-packages/gym/core.py", line 289, in reset
    return self.env.reset(**kwargs)
  File "/home/dang/anaconda3/envs/mine/lib/python3.7/site-packages/gym/core.py", line 264, in reset
    observation = self.env.reset(**kwargs)
  File "/home/dang/anaconda3/envs/mine/lib/python3.7/site-packages/gym/wrappers/time_limit.py", line 25, in reset
    return self.env.reset(**kwargs)
  File "/home/dang/.local/lib/python3.7/site-packages/minerl/env/_singleagent.py", line 22, in reset
    multi_obs = super().reset()
  File "/home/dang/.local/lib/python3.7/site-packages/minerl/env/_multiagent.py", line 455, in reset
    self._setup_instances()
  File "/home/dang/.local/lib/python3.7/site-packages/minerl/env/_multiagent.py", line 556, in _setup_instances
    self.instances.extend([f.result() for f in instance_futures])
  File "/home/dang/.local/lib/python3.7/site-packages/minerl/env/_multiagent.py", line 556, in <listcomp>
    self.instances.extend([f.result() for f in instance_futures])
  File "/home/dang/anaconda3/envs/mine/lib/python3.7/concurrent/futures/_base.py", line 428, in result
    return self.__get_result()
  File "/home/dang/anaconda3/envs/mine/lib/python3.7/concurrent/futures/_base.py", line 384, in __get_result
    raise self._exception
  File "/home/dang/anaconda3/envs/mine/lib/python3.7/concurrent/futures/thread.py", line 57, in run
    result = self.fn(*self.args, **self.kwargs)
  File "/home/dang/.local/lib/python3.7/site-packages/minerl/env/_multiagent.py", line 807, in _get_new_instance
    instance.launch(replaceable=self._is_fault_tolerant)
  File "/home/dang/.local/lib/python3.7/site-packages/minerl/env/malmo.py", line 486, in launch
    ignore=shutil.ignore_patterns('**.lock'))
  File "/home/dang/anaconda3/envs/mine/lib/python3.7/shutil.py", line 368, in copytree
    raise Error(errors)
